Workbook

Sheet PO Summary
A1: 52 Paramount Terrace: Final Material Purchase Summary
A2: Tile, flooring and stone · 25% waste · recalculated from permit set A1-A7 (09/07/2026), bath plans, cabinet sheets and kitchen render · prepared 09/25/2026
A4: Product | B4: Recommended spec (CA contractor) | C4: Where | D4: Net SF (calc) | E4: Waste | F4: Order SF | G4: Box / sheet coverage (SF) | H4: Boxes to order | I4: SF delivered | J4: Status | K4: Notes
A5: Flooring | B5: Rigid-core LVP (SPC), light natural oak look per render, ~9" x 60" plank, 20-mil wear layer, attached pad, waterproof | C5: All rooms, 1F + 2F (not baths) | D5: =SUMIFS(Takeoff!$J$5:$J$64,Takeoff!$B$5:$B$64,"Flooring") -> 1253.1549 | E5: =Assumptions!$B$5 -> 0.25 | F5: =ROUNDUP(D5*(1+E5),0) -> 1567 | G5: 23 | H5: =ROUNDUP(F5/G5,0) -> 69 | I5: =H5*G5 -> 1587 | J5: SCALED | K5: Continuous with no transitions between rooms. Because every floor is new, the permit's 'match existing' note is met. Stairs are on Setting Materials. About 190 SF (halls, closets, stair landing) is scaled off the plan, so field verify.
A6: Bath floor tile | B6: 12" x 24" rectified porcelain, matte, DCOF >= 0.42 wet, warm light neutral | C6: Baths 1, 2, 3 (outside shower) | D6: =SUMIFS(Takeoff!$J$5:$J$64,Takeoff!$B$5:$B$64,"Bath floor tile") -> 120.68967 | E6: =Assumptions!$B$5 -> 0.25 | F6: =ROUNDUP(D6*(1+E6),0) -> 151 | G6: 15.5 | H6: =ROUNDUP(F6/G6,0) -> 10 | I6: =H6*G6 -> 155 | J6: VERIFIED | K6: One product and one dye lot for all 3 baths. Lay offset 1/3, not 1/2, to control lippage.
A7: Shower wall tile | B7: 12" x 24" porcelain, same series as the floor (or matching wall body), stacked or 1/3 offset | C7: 3 showers, floor to ceiling | D7: =SUMIFS(Takeoff!$J$5:$J$64,Takeoff!$B$5:$B$64,"Shower wall tile") -> 250.08257 | E7: =Assumptions!$B$5 -> 0.25 | F7: =ROUNDUP(D7*(1+E7),0) -> 313 | G7: 15.5 | H7: =ROUNDUP(F7/G7,0) -> 21 | I7: =H7*G7 -> 325.5 | J7: VERIFIED | K7: Includes window returns, niche returns and curb faces. Tile is inside the shower only.
A8: Shower floor mosaic | B8: 2" x 2" porcelain mosaic on 12" x 12" mesh, matte / slip-resistant, same color family | C8: 3 shower pans | D8: =SUMIFS(Takeoff!$J$5:$J$64,Takeoff!$B$5:$B$64,"Shower floor mosaic") -> 37.671007 | E8: =Assumptions!$B$5 -> 0.25 | F8: =ROUNDUP(D8*(1+E8),0) -> 48 | G8: 10 | H8: =ROUNDUP(F8/G8,0) -> 5 | I8: =H8*G8 -> 50 | J8: VERIFIED | K8: Center drain with 1/4" per ft slope. Small tiles follow the 4-way slope.
A9: Backsplash tile | B9: 8" x 8" encaustic-look (cement pattern) porcelain per render | C9: Kitchen, counter to uppers | D9: =SUMIFS(Takeoff!$J$5:$J$64,Takeoff!$B$5:$B$64,"Backsplash tile") -> 19.138889 | E9: =Assumptions!$B$5 -> 0.25 | F9: =ROUNDUP(D9*(1+E9),0) -> 24 | G9: 10.76 | H9: =ROUNDUP(F9/G9,0) -> 3 | I9: =H9*G9 -> 32.28 | J9: ASSUMPTION | K9: Window sills are assumed 4" above the counter (render). If they're higher, re-run: the full band is 31.1 SF net / 39 SF order.
A10: Quartz countertop | B10: 3 cm quartz, white / soft-vein per render, eased edge, undermount sink | C10: Kitchen + 3 curb caps + 3 niche sills | D10: =Countertop!B10 -> 33.18099 | E10: =Assumptions!$B$5 -> 0.25 | F10: =ROUNDUP(D10*(1+E10),0) -> 42 | G10: =Countertop!B9 -> 55.125 | H10: 1 | I10: =H10*G10 -> 55.125 | J10: VERIFIED | K10: 1 JUMBO slab (126" x 63"). Countertops fit either size, but only the jumbo leaves a 12" strip for the curb caps. See Countertop tab.
A11: Unit for column H: boxes (tile/LVP), sheets-boxes (mosaic), slabs (quartz). Yellow cells = replace with the selected product's box coverage before release.
A13: Breakdown by location (use for staging deliveries)
A14: Location | B14: Level | C14: Floor tile net | D14: Floor tile order | E14: Wall tile net | F14: Wall tile order | G14: Mosaic net | H14: Mosaic order | I14: Total order SF
A15: Bath 3 | B15: 1F | C15: =SUMIFS(Takeoff!$J$5:$J$64,Takeoff!$B$5:$B$64,"Bath floor tile",Takeoff!$D$5:$D$64,"Bath 3") -> 47.167969 | D15: =ROUNDUP(C15*(1+Assumptions!$B$5),0) -> 59 | E15: =SUMIFS(Takeoff!$J$5:$J$64,Takeoff!$B$5:$B$64,"Shower wall tile",Takeoff!$D$5:$D$64,"Bath 3") -> 101.92665 | F15: =ROUNDUP(E15*(1+Assumptions!$B$5),0) -> 128 | G15: =SUMIFS(Takeoff!$J$5:$J$64,Takeoff!$B$5:$B$64,"Shower floor mosaic",Takeoff!$D$5:$D$64,"Bath 3") -> 17.34375 | H15: =ROUNDUP(G15*(1+Assumptions!$B$5),0) -> 22 | I15: =D15+F15+H15 -> 209
A16: Bath 1 | B16: 2F | C16: =SUMIFS(Takeoff!$J$5:$J$64,Takeoff!$B$5:$B$64,"Bath floor tile",Takeoff!$D$5:$D$64,"Bath 1") -> 44.074002 | D16: =ROUNDUP(C16*(1+Assumptions!$B$5),0) -> 56 | E16: =SUMIFS(Takeoff!$J$5:$J$64,Takeoff!$B$5:$B$64,"Shower wall tile",Takeoff!$D$5:$D$64,"Bath 1") -> 92.341797 | F16: =ROUNDUP(E16*(1+Assumptions!$B$5),0) -> 116 | G16: =SUMIFS(Takeoff!$J$5:$J$64,Takeoff!$B$5:$B$64,"Shower floor mosaic",Takeoff!$D$5:$D$64,"Bath 1") -> 11.783854 | H16: =ROUNDUP(G16*(1+Assumptions!$B$5),0) -> 15 | I16: =D16+F16+H16 -> 187
A17: Bath 2 | B17: 2F | C17: =SUMIFS(Takeoff!$J$5:$J$64,Takeoff!$B$5:$B$64,"Bath floor tile",Takeoff!$D$5:$D$64,"Bath 2") -> 29.4477 | D17: =ROUNDUP(C17*(1+Assumptions!$B$5),0) -> 37 | E17: =SUMIFS(Takeoff!$J$5:$J$64,Takeoff!$B$5:$B$64,"Shower wall tile",Takeoff!$D$5:$D$64,"Bath 2") -> 55.814128 | F17: =ROUNDUP(E17*(1+Assumptions!$B$5),0) -> 70 | G17: =SUMIFS(Takeoff!$J$5:$J$64,Takeoff!$B$5:$B$64,"Shower floor mosaic",Takeoff!$D$5:$D$64,"Bath 2") -> 8.5434028 | H17: =ROUNDUP(G17*(1+Assumptions!$B$5),0) -> 11 | I17: =D17+F17+H17 -> 118
A18: Total | C18: =SUM(C15:C17) -> 120.68967 | D18: =SUM(D15:D17) -> 152 | E18: =SUM(E15:E17) -> 250.08257 | F18: =SUM(F15:F17) -> 314 | G18: =SUM(G15:G17) -> 37.671007 | H18: =SUM(H15:H17) -> 48 | I18: =SUM(I15:I17) -> 514
A19: Per-bath orders are rounded separately, so their sum can run 1-2 SF above the product total in the table above. Order to the product total.
A21: Flooring by level
A22: Level | D22: Net SF | F22: Order SF
A23: 1F | D23: =SUMIFS(Takeoff!$J$5:$J$64,Takeoff!$B$5:$B$64,"Flooring",Takeoff!$E$5:$E$64,"1F") -> 461.27986 | F23: =ROUNDUP(D23*(1+Assumptions!$B$5),0) -> 577
A24: 2F | D24: =SUMIFS(Takeoff!$J$5:$J$64,Takeoff!$B$5:$B$64,"Flooring",Takeoff!$E$5:$E$64,"2F") -> 791.875 | F24: =ROUNDUP(D24*(1+Assumptions!$B$5),0) -> 990
A25: Total | D25: =D23+D24 -> 1253.1549 | F25: =F23+F24 -> 1567
A26: Level totals are rounded per level, so they can run 1 SF above the flooring total.
A28: Color key: Blue = input · Green = link to another tab · Black = formula · Yellow = replace with the selected product's data. Status: VERIFIED / SCALED / ASSUMPTION / RECOMMENDED / HOLD.

Sheet Assumptions
A1: Assumptions & Inputs
A2: Blue = input you can change. Every formula in the workbook reads from here. 52 Paramount Terrace, SF 94118 · Block/Lot 1166/043
A4: Parameter | B4: Value | C4: Unit | D4: Source / basis
A5: Waste factor (all tile, flooring, stone) | B5: 0.25 | C5: % | D5: User instruction: 25% on every line. Also covers pattern matching on the backsplash.
A6: Bathroom wall / ceiling height | B6: 101.125 | C6: in | D6: User-provided: 101 1/8". Shower tile runs floor to ceiling.
A7: Countertop depth | B7: 25.5 | C7: in | D7: 24" cabinet depth (2'-0" on the lower cabinet sheet) + 1.5" front overhang
A8: Backsplash height (counter to underside of uppers) | B8: 18 | C8: in | D8: Standard 36" counter to 54" upper bottom. The render shows tile running from counter to uppers.
A9: Window sill height above countertop | B9: 4 | C9: in | D9: From the render (short tile band under the sink window). FIELD VERIFY: sill heights for W3, W5 and W6 aren't on the plans.
A10: Niche width (finished opening) | B10: 12 | C10: in | D10: Recommended: 12" x 24" prefab waterproof niche, fits between 16" o.c. studs
A11: Niche height (finished opening) | B11: 24 | C11: in | D11: Recommended
A12: Niche depth (tiled returns) | B12: 3.5 | C12: in | D12: 2x4 stud cavity, less backer
A13: Window return depth (W11 jambs/sill/head) | B13: 5 | C13: in | D13: 2x4 wall + backer + tile. Field verify.
A14: Curb face tile strip (outside 4.5" + inside 5") | B14: 9.5 | C14: in | D14: Recommended 4.5" curb (CPC 408.5: 2"-9" above drain). The quartz cap covers the curb top.
A15: Curb cap width (quartz) | B15: 4.5 | C15: in | D15: Matches a 4 1/2" foam curb. At 4.5" two rows fit in the jumbo slab's 9.5" leftover strip (5" does not).
A16: Bath 1 partition wall end (tiled) | B16: 4.5 | C16: in | D16: Wall end exposed at the glass line
... A23: Backer board / membrane overage | B23: 0.15 | C23: % | D23: Cut waste on board

Sheet Takeoff
A1: Takeoff Detail: every line, every dimension
A2: Dimensions in inches from the permit set, bath plans and cabinet sheets. Net SF = Length x Width x Count / 144, or the plan label SF x Count. Negative count = deduction.
A4: ID | B4: Product | C4: Item | D4: Location | E4: Level | F4: Length (in) | G4: Width / Height (in) | H4: Count (+/-) | I4: Plan label SF | J4: Net SF | K4: Status | L4: Source / notes
A5: FLOORING: Rigid-core LVP, all rooms (bathrooms get tile)
A6: F1 | B6: Flooring | C6: Bedroom 2 (room) | D6: Bedroom 2 | E6: 1F | F6: 147.5 | G6: 137.5 | H6: 1 | J6: =IF(I6<>"",I6*H6,F6*G6*H6/144) -> 140.84201 | K6: VERIFIED | L6: A2: 8'-8" + 3'-7 1/2" = 12'-3 1/2" wide x 11'-5 1/2"
A7: F2 | B7: Flooring | C7: Bedroom 2 closet | D7: Bedroom 2 | E7: 1F | F7: 103 | G7: 24 | H7: 1 | J7: =IF(I7<>"",I7*H7,F7*G7*H7/144) -> 17.166667 | K7: SCALED | L7: 2'-0" deep dimensioned, length scaled ~8'-7". Room + closet = 158 SF vs 156.9 SF label, which checks out.
A8: F3 | B8: Flooring | C8: Bedroom 3 incl. closet | D8: Bedroom 3 | E8: 1F | F8: 129 | G8: 137.5 | H8: 1 | J8: =IF(I8<>"",I8*H8,F8*G8*H8/144) -> 123.17708 | K8: VERIFIED | L8: A2: 10'-9" x 11'-5 1/2" = 123.2 SF (plan label 116 SF is low). Over new floor assembly on the garage slab, A7 detail 4.
A9: F4 | B9: Flooring | C9: Laundry (W/D) | D9: Laundry | E9: 1F | H9: 1 | I9: 16.5 | J9: =IF(I9<>"",I9*H9,F9*G9*H9/144) -> 16.5 | K9: VERIFIED | L9: A2 plan label
A10: F5 | B10: Flooring | C10: Linen | D10: Linen | E10: 1F | H10: 1 | I10: 11.8 | J10: =IF(I10<>"",I10*H10,F10*G10*H10/144) -> 11.8 | K10: VERIFIED | L10: A2 plan label
A11: F6 | B11: Flooring | C11: Garage nook | D11: Garage nook | E11: 1F | H11: 1 | I11: 19.9 | J11: =IF(I11<>"",I11*H11,F11*G11*H11/144) -> 19.9 | K11: VERIFIED | L11: A2 plan label
A12: F7 | B12: Flooring | C12: Hall | D12: 1F Hall | E12: 1F | F12: 205 | G12: 45 | H12: 1 | J12: =IF(I12<>"",I12*H12,F12*G12*H12/144) -> 64.0625 | K12: SCALED | L12: Not dimensioned. Scaled ~17'-1" x 3'-9". Field measure.
A13: F8 | B13: Flooring | C13: Entry / stair landing area | D13: 1F Stairs | E13: 1F | F13: 151.5 | G13: 81.5 | H13: 1 | J13: =IF(I13<>"",I13*H13,F13*G13*H13/144) -> 85.744792 | K13: SCALED | L13: 12'-7 1/2" dimensioned, depth scaled ~6'-9"
A14: F9 | B14: Flooring | C14: Less stair flight footprint | D14: 1F Stairs | E14: 1F | F14: 77 | G14: 33.5 | H14: -1 | J14: =IF(I14<>"",I14*H14,F14*G14*H14/144) -> -17.913194 | K14: SCALED | L14: Stair treads are counted separately on Setting Materials
A15: F10 | B15: Flooring | C15: Living room | D15: Living room | E15: 2F | H15: 1 | I15: 341 | J15: =IF(I15<>"",I15*H15,F15*G15*H15/144) -> 341 | K15: VERIFIED | L15: A3 plan label
A16: F11 | B16: Flooring | C16: Kitchen & dining | D16: Kitchen & dining | E16: 2F | H16: 1 | I16: 252 | J16: =IF(I16<>"",I16*H16,F16*G16*H16/144) -> 252 | K16: VERIFIED | L16: A3 plan label
A17: F12 | B17: Flooring | C17: Less base cabinets, window wall (excl. range) | D17: Kitchen & dining | E17: 2F | F17: 133.875 | G17: 24 | H17: -1 | J17: =IF(I17<>"",I17*H17,F17*G17*H17/144) -> -22.3125 | K17: VERIFIED | L17: 34 1/4 + 34 1/8 + 19 1/2 + 46. Floating LVP installs AFTER the cabinets and doesn't go under them. It still runs under the range, fridge and DW.
A18: F13 | B18: Flooring | C18: Less base cabinets, left wall (excl. DW and corner) | D18: Kitchen & dining | E18: 2F | F18: 31.375 | G18: 24 | H18: -1 | J18: =IF(I18<>"",I18*H18,F18*G18*H18/144) -> -5.2291667 | K18: VERIFIED | L18: 45 3/8 - 24 corner + 10 filler/cabinet
A19: F14 | B19: Flooring | C19: Primary bedroom | D19: Primary bedroom | E19: 2F | H19: 1 | I19: 156 | J19: =IF(I19<>"",I19*H19,F19*G19*H19/144) -> 156 | K19: VERIFIED | L19: A3 plan label
A20: F15 | B20: Flooring | C20: Pantry | D20: Pantry | E20: 2F | H20: 1 | I20: 20 | J20: =IF(I20<>"",I20*H20,F20*G20*H20/144) -> 20 | K20: VERIFIED | L20: A3 plan label
A21: F16 | B21: Flooring | C21: Primary closet | D21: Primary closet | E21: 2F | F21: 64 | G21: 42 | H21: 1 | J21: =IF(I21<>"",I21*H21,F21*G21*H21/144) -> 18.666667 | K21: SCALED | L21: 5'-4" dimensioned, depth scaled ~3'-6"
A22: F17 | B22: Flooring | C22: Hall | D22: 2F Hall | E22: 2F | F22: 38 | G22: 90 | H22: 1 | J22: =IF(I22<>"",I22*H22,F22*G22*H22/144) -> 23.75 | K22: SCALED | L22: Not dimensioned. Scaled ~3'-2" x 7'-6".
A23: F18 | B23: Flooring | C23: Foyer | D23: Foyer | E23: 2F | H23: 1 | I23: 8 | J23: =IF(I23<>"",I23*H23,F23*G23*H23/144) -> 8 | K23: VERIFIED | L23: A3 existing-plan label (unchanged)
A24: BATHROOM FLOOR TILE: outside the shower
A25: BF1 | B25: Bath floor tile | C25: Room gross | D25: Bath 3 | E25: 1F | F25: 67.5 | G25: 137.625 | H25: 1 | J25: =IF(I25<>"",I25*H25,F25*G25*H25/144) -> 64.511719 | K25: VERIFIED | L25: Bath plan 67 1/2" x 137 5/8" = 64.5 SF (matches label)
A26: BF2 | B26: Bath floor tile | C26: Less shower pan | D26: Bath 3 | E26: 1F | F26: 67.5 | G26: 37 | H26: -1 | J26: =IF(I26<>"",I26*H26,F26*G26*H26/144) -> -17.34375 | K26: VERIFIED | L26: Shower 67 1/2" x 37"
A27: BF3 | B27: Bath floor tile | C27: Room gross | D27: Bath 1 | E27: 2F | F27: 90.25 | G27: 89.125 | H27: 1 | J27: =IF(I27<>"",I27*H27,F27*G27*H27/144) -> 55.857856 | K27: VERIFIED | L27: Common bath 90 1/4" x 89 1/8" = 55.9 SF (label 60 SF is high)
A28: BF4 | B28: Bath floor tile | C28: Less shower pan | D28: Bath 1 | E28: 2F | F28: 37.5 | G28: 45.25 | H28: -1 | J28: =IF(I28<>"",I28*H28,F28*G28*H28/144) -> -11.783854 | K28: VERIFIED | L28: Shower 37 1/2" x 45 1/4"
A29: BF5 | B29: Bath floor tile | C29: Room gross | D29: Bath 2 | E29: 2F | F29: 70.25 | G29: 77.875 | H29: 1 | J29: =IF(I29<>"",I29*H29,F29*G29*H29/144) -> 37.991102 | K29: VERIFIED | L29: Primary bath 70 1/4" x 77 7/8" = 38.0 SF
A30: BF6 | B30: Bath floor tile | C30: Less shower pan | D30: Bath 2 | E30: 2F | F30: 32.375 | G30: 38 | H30: -1 | J30: =IF(I30<>"",I30*H30,F30*G30*H30/144) -> -8.5434028 | K30: VERIFIED | L30: Shower 32 3/8" x 38"
A31: SHOWER WALL TILE: inside the shower only, floor to ceiling
A32: SW1 | B32: Shower wall tile | C32: Back wall (exterior, W11) | D32: Bath 3 | E32: 1F | F32: 67.5 | G32: =Assumptions!$B$6 -> 101.125 | H32: 1 | J32: =IF(I32<>"",I32*H32,F32*G32*H32/144) -> 47.402344 | K32: VERIFIED | L32: Full room width
A33: SW2 | B33: Shower wall tile | C33: Left side wall (valve wall) | D33: Bath 3 | E33: 1F | F33: 37 | G33: =Assumptions!$B$6 -> 101.125 | H33: 1 | J33: =IF(I33<>"",I33*H33,F33*G33*H33/144) -> 25.983507 | K33: VERIFIED
A34: SW3 | B34: Shower wall tile | C34: Right side wall (niche wall) | D34: Bath 3 | E34: 1F | F34: 37 | G34: =Assumptions!$B$6 -> 101.125 | H34: 1 | J34: =IF(I34<>"",I34*H34,F34*G34*H34/144) -> 25.983507 | K34: VERIFIED | L34: Interior wall shared with Bedroom 3
A35: SW4 | B35: Shower wall tile | C35: Less window W11 | D35: Bath 3 | E35: 1F | F35: 30 | G35: 41.25 | H35: -1 | J35: =IF(I35<>"",I35*H35,F35*G35*H35/144) -> -8.59375 | K35: VERIFIED | L35: W11 30" x 41 1/4" per A5 size (A5 mislabels its location)
A36: SW5 | B36: Shower wall tile | C36: Add W11 returns (jambs, sill, head) | D36: Bath 3 | E36: 1F | F36: 142.5 | G36: =Assumptions!$B$13 -> 5 | H36: 1 | J36: =IF(I36<>"",I36*H36,F36*G36*H36/144) -> 4.9479167 | K36: ASSUMPTION | L36: Perimeter 2x30 + 2x41.25. Return depth per Assumptions.
A37: SW6 | B37: Shower wall tile | C37: Niche returns (opening/back net zero) | D37: Bath 3 | E37: 1F | F37: =2*(Assumptions!$B$10+Assumptions!$B$11) -> 72 | G37: =Assumptions!$B$12 -> 3.5 | H37: 1 | J37: =IF(I37<>"",I37*H37,F37*G37*H37/144) -> 1.75 | K37: RECOMMENDED | L37: Tiling the niche back replaces the wall tile cut out for the opening
A38: SW7 | B38: Shower wall tile | C38: Curb faces | D38: Bath 3 | E38: 1F | F38: 67.5 | G38: =Assumptions!$B$14 -> 9.5 | H38: 1 | J38: =IF(I38<>"",I38*H38,F38*G38*H38/144) -> 4.453125 | K38: RECOMMENDED | L38: Straight curb across the full width
A39: SW8 | B39: Shower wall tile | C39: Back wall (exterior, valve wall) | D39: Bath 1 | E39: 2F | F39: 37.5 | G39: =Assumptions!$B$6 -> 101.125 | H39: 1 | J39: =IF(I39<>"",I39*H39,F39*G39*H39/144) -> 26.334635 | K39: VERIFIED
A40: SW9 | B40: Shower wall tile | C40: Left side wall (niche wall) | D40: Bath 1 | E40: 2F | F40: 45.25 | G40: =Assumptions!$B$6 -> 101.125 | H40: 1 | J40: =IF(I40<>"",I40*H40,F40*G40*H40/144) -> 31.777127 | K40: VERIFIED | L40: Interior wall
A41: SW10 | B41: Shower wall tile | C41: Partition wall (door side) | D41: Bath 1 | E41: 2F | F41: 37.5 | G41: =Assumptions!$B$6 -> 101.125 | H41: 1 | J41: =IF(I41<>"",I41*H41,F41*G41*H41/144) -> 26.334635 | K41: VERIFIED | L41: Full-height partition between the shower and the door
...

Sheet Countertop
A1: Countertop & Slab Check
A2: Quartz, 3 cm, eased edge (per render). The fabricator templates on site after the cabinets are set; nothing is cut off these drawings.
A4: Input / check | B4: Jumbo slab | C4: Standard slab | D4: Notes
A5: Slab length (in) | B5: 126 | C5: 120 | D5: Typical quartz sizes. Confirm with the supplier.
A6: Slab width (in) | B6: 63 | C6: 55
A7: Edge trim each side (in) | B7: 1 | C7: 1 | D7: Factory edge removed
A8: Saw kerf (in) | B8: 0.25 | C8: 0.25
A9: Slab area (SF) | B9: =B5*B6/144 -> 55.125 | C9: =C5*C6/144 -> 45.833333
A10: Countertop net SF (CT1-CT3) | B10: =SUM(Takeoff!J60:J62) -> 33.18099 | C10: =SUM(Takeoff!J60:J62) -> 33.18099
A11: Countertop SF with waste | B11: =B10*(1+Assumptions!$B$5) -> 41.476237 | C11: =C10*(1+Assumptions!$B$5) -> 41.476237
A12: Strip 1: CT1 length needed (in) | B12: =87.875 -> 87.875 | C12: =87.875 -> 87.875 | D12: Sink piece
A13: Strip 2: CT2 + CT3 + kerf (in) | B13: =53.5+46+B8 -> 99.75 | C13: =53.5+46+C8 -> 99.75
A14: Usable length (in) | B14: =B5-2*B7 -> 124 | C14: =C5-2*C7 -> 118
A15: Width left after two 25.5" strips (in) | B15: =B6-2*B7-2*Assumptions!$B$7-2*B8 -> 9.5 | C15: =C6-2*C7-2*Assumptions!$B$7-2*C8 -> 1.5 | D15: Leftover strip for curb caps
A16: Curb-cap rows that fit (at cap width + kerf) | B16: =INT(B15/(Assumptions!$B$15+B8)) -> 2 | C16: =INT(C15/(Assumptions!$B$15+C8)) -> 0
A17: Curb caps total length needed (in) | B17: =183.125 -> 183.125 | C17: =183.125 -> 183.125 | D17: 67.5 + 45.25 + 70.375
A18: Countertops fit on one slab? | B18: =IF(AND(B12<=B14,B13<=B14),"YES","NO") -> YES | C18: =IF(AND(C12<=C14,C13<=C14),"YES","NO") -> YES
A19: Curb caps also fit from the same slab? | B19: =IF(B16*B14>=B17,"YES","NO") -> YES | C19: =IF(C16*C14>=C17,"YES","NO") -> NO | D19: The 3 niche sills (12"x4") come from the strip 1 remnant
A20: Waste check: SF with waste <= slab SF? | B20: =IF(B11<=B9,"YES","NO") -> YES | C20: =IF(C11<=C9,"YES","NO") -> YES
A21: RECOMMENDATION | B21: ORDER 1 JUMBO | D21: A jumbo 126"x63" slab covers all countertops, the 3 curb caps and the niche sills. A standard slab fits the countertops but not the caps.
A23: Piece list (templated sizes will change slightly)
A24: Piece | B24: Length (in) | C24: Depth (in) | D24: Notes
A25: CT1 Window wall, corner to range | B25: 87.875 | C25: =Assumptions!$B$7 -> 25.5 | D25: sink cutout; undermount recommended
A26: CT2 Left wall leg | B26: 53.5 | C26: =Assumptions!$B$7 -> 25.5 | D26: seam at corner; not at the sink
A27: CT3 Right of range | B27: 46 | C27: =Assumptions!$B$7 -> 25.5 | D27: exposed end: finished/eased end
A28: Curb cap Bath 3 | B28: 67.5 | C28: =Assumptions!$B$15 -> 4.5 | D28: 4 1/2" wide, pitch 1/8" toward shower
A29: Curb cap Bath 1 | B29: 45.25 | C29: =Assumptions!$B$15 -> 4.5 | D29: 4 1/2" wide
A30: Curb cap Bath 2 (L, 2 pcs) | B30: 70.375 | C30: =Assumptions!$B$15 -> 4.5 | D30: 32 3/8" + 38", mitered corner
A31: Niche sills x3 | B31: 12 | C31: 4 | D31: 4" deep, pitched

Sheet Showers
A1: Shower Specifications (contractor recommendation)
A2: Full glass enclosures, tile inside the shower only, floor to ceiling at 101 1/8". Based on the permit plans; field verify after framing.
A4: Spec item | B4: Bath 3 (1F) | C4: Bath 1 (2F, common) | D4: Bath 2 (2F, primary)
A5: Shower size (in) | B5: 67 1/2" x 37" | C5: 37 1/2" x 45 1/4" | D5: 32 3/8" x 38"
A6: Pan area (SF) | B6: =SUMIFS(Takeoff!$J$5:$J$64,Takeoff!$B$5:$B$64,"Shower floor mosaic",Takeoff!$D$5:$D$64,"Bath 3") -> 17.34375 | C6: =SUMIFS(Takeoff!$J$5:$J$64,Takeoff!$B$5:$B$64,"Shower floor mosaic",Takeoff!$D$5:$D$64,"Bath 1") -> 11.783854 | D6: =SUMIFS(Takeoff!$J$5:$J$64,Takeoff!$B$5:$B$64,"Shower floor mosaic",Takeoff!$D$5:$D$64,"Bath 2") -> 8.5434028
A7: Wall tile net SF | B7: =SUMIFS(Takeoff!$J$5:$J$64,Takeoff!$B$5:$B$64,"Shower wall tile",Takeoff!$D$5:$D$64,"Bath 3") -> 101.92665 | C7: =SUMIFS(Takeoff!$J$5:$J$64,Takeoff!$B$5:$B$64,"Shower wall tile",Takeoff!$D$5:$D$64,"Bath 1") -> 92.341797 | D7: =SUMIFS(Takeoff!$J$5:$J$64,Takeoff!$B$5:$B$64,"Shower wall tile",Takeoff!$D$5:$D$64,"Bath 2") -> 55.814128
A8: Tiled walls | B8: 3: back (exterior, W11), left (valve), right | C8: 3: back (exterior, valve), left, partition by door | D8: 2: back (exterior, valve), left (exterior, W13 side)
A9: Open side(s) / glass | B9: Front (67 1/2") | C9: Right side (45 1/4") | D9: Front (32 3/8") + side (38"), 90° corner
A10: Glass enclosure | B10: Inline: fixed panel + 24" swing door | C10: Inline: fixed panel + 24" swing door | D10: Corner: door + fixed panel on the front, fixed return panel on the side
A11: Glass spec | B11: 3/8" tempered, 78" high, clear/low-iron, CRC R308.4.5 safety glazing | C11: same | D11: same
A12: Door opening | B12: Min. 22" clear (CPC 408.5). Swing out. | C12: Min. 22" clear | D12: Min. 22" clear. The 32 3/8" front leaves room for a ~24" door + ~8" panel.
A13: Measure glass | B13: After tile is complete | C13: After tile is complete | D13: After tile is complete
A14: Niche | B14: 1 @ 12" W x 24" H x 3 1/2" D, prefab waterproof | C14: 1 @ 12" x 24" x 3 1/2" | D14: 1 @ 12" x 24" x 3 1/2"
A15: Niche location | B15: Right wall (interior, shared with Bedroom 3), centered, bottom at ~42" AFF | C15: Left wall (interior), centered, bottom at ~42" AFF | D15: Left wall. It's an EXTERIOR wall, so keep insulation behind the niche (1" rigid foam + prefab niche) per Title 24, or confirm 2x6 framing.
A16: Niche sill | B16: Quartz remnant, pitched | C16: Quartz remnant, pitched | D16: Quartz remnant, pitched
A17: Window in shower | B17: W11 30" x 41 1/4": tempered glass, vinyl or fiberglass frame, sloped tiled sill, waterproofed returns | C17: None | D17: None (W13 is outside the shower)
A18: Curb | B18: 4 1/2" high foam curb, 67 1/2" long | C18: 4 1/2" high, 45 1/4" long | D18: 4 1/2" L-curb, 32 3/8" + 38"
A19: Curbless? | B19: Not recommended: needs framing recess | C19: Not recommended: needs 2F joist recess, and the permit says no structural changes | D19: Not recommended (same)
... A26: Valve wall | B26: Left side wall | C26: Back wall | D26: Back wall

Sheet Setting Materials
A1: Setting Materials & Accessories
A2: Quantities come from the net SF on the Takeoff tab. Coverage rates are on the Assumptions tab. Confirm against the selected manufacturer's data sheets.
A4: Item | B4: Basis / formula | C4: Qty (calc) | D4: Order qty | E4: Unit | F4: Notes
A5: LFT mortar, 50 lb (12x24 floor + walls + curbs) | B5: (floor + wall tile net) x 1.10 / coverage | C5: =(SUMIFS(Takeoff!$J$5:$J$64,Takeoff!$B$5:$B$64,"Bath floor tile")+SUMIFS(Takeoff!$J$5:$J$64,Takeoff!$B$5:$B$64,"Shower wall tile"))*1.1/Assumptions!$B$17 -> 10.196237 | D5: =ROUNDUP(C5,0) -> 11 | E5: bags | F5: Large-and-heavy-tile mortar. Back-butter the 12x24s.
A6: Modified thinset, 50 lb (mosaic + backsplash) | B6: (mosaic + backsplash) x 1.10 / coverage | C6: =(SUMIFS(Takeoff!$J$5:$J$64,Takeoff!$B$5:$B$64,"Shower floor mosaic")+SUMIFS(Takeoff!$J$5:$J$64,Takeoff!$B$5:$B$64,"Backsplash tile"))*1.1/Assumptions!$B$18 -> 0.78113607 | D6: =ROUNDUP(C6,0) -> 1 | E6: bags | F6: White thinset under light-colored tile
A7: Grout: 12x24 porcelain (1/8" joint, 3/8" thick) | B7: lb/SF = (L+W)/(LxW) x joint x depth x 144 x density | C7: =(SUMIFS(Takeoff!$J$5:$J$64,Takeoff!$B$5:$B$64,"Bath floor tile")+SUMIFS(Takeoff!$J$5:$J$64,Takeoff!$B$5:$B$64,"Shower wall tile"))*((12+24)/(12*24))*0.125*0.375*144*Assumptions!$B$19*1.15 -> 20.866367 | D7: =ROUNDUP(C7,0) -> 21 | E7: lb | F7: High-performance or urethane grout recommended in showers. Round to the manufacturer's pack.
A8: Grout: 2x2 mosaic (1/8" joint, 1/4" thick) | B8: same formula | C8: =SUMIFS(Takeoff!$J$5:$J$64,Takeoff!$B$5:$B$64,"Shower floor mosaic")*((2+2)/(2*2))*0.125*0.25*144*Assumptions!$B$19*1.15 -> 11.306953 | D8: =ROUNDUP(C8,0) -> 12 | E8: lb | F8: Epoxy grout recommended on shower floors
A9: Grout: 8x8 backsplash (1/16" joint, 3/8" thick) | B9: same formula | C9: =SUMIFS(Takeoff!$J$5:$J$64,Takeoff!$B$5:$B$64,"Backsplash tile")*((8+8)/(8*8))*0.0625*0.375*144*Assumptions!$B$19*1.15 -> 1.0771008 | D9: =ROUNDUP(C9,0) -> 2 | E9: lb | F9: Unsanded
A10: Waterproof foam backer board, 4'x8' | B10: gross shower wall SF x (1+overage) / 32 | C10: =SUMIFS(Takeoff!$J$5:$J$64,Takeoff!$B$5:$B$64,"Shower wall tile",Takeoff!$H$5:$H$64,">0")*(1+Assumptions!$B$23)/Assumptions!$B$20 -> 9.2961804 | D10: =ROUNDUP(C10,0) -> 10 | E10: sheets | F10: Plus manufacturer seam band, corners, pipe seals and fasteners/washers
A11: Pre-sloped shower tray or mortar bed kit | B11: 1 per shower | C11: 3 | D11: =ROUNDUP(C11,0) -> 3 | E11: each | F11: Bath 3 tray must be trimmed to 67 1/2" x 37"
A12: Bonding-flange shower drain, 2", 4" square grate | B12: 1 per shower | C12: 3 | D12: =ROUNDUP(C12,0) -> 3 | E12: each
A13: Prefab foam shower curb | B13: Bath 2 L-curb = 2 pcs | C13: 4 | D13: =ROUNDUP(C13,0) -> 4 | E13: pcs | F13: 4 1/2" high
A14: Prefab waterproof niche, 12" x 24" | B14: 1 per shower (user confirmed niches) | C14: 3 | D14: =ROUNDUP(C14,0) -> 3 | E14: each | F14: Bath 2 niche in exterior wall: add rigid foam behind
A15: Uncoupling / waterproof floor membrane | B15: bath floor net x (1+overage) / roll | C15: =SUMIFS(Takeoff!$J$5:$J$64,Takeoff!$B$5:$B$64,"Bath floor tile")*(1+Assumptions!$B$23)/Assumptions!$B$21 -> 2.570243 | D15: =ROUNDUP(C15,0) -> 3 | E15: rolls | F15: All 3 bath floors
A16: Tile edge trim (vertical edges at glass) | B16: 6 edges x 101 1/8"; stick 98.5" is too short, so 2 pcs per edge | C16: 12 | D16: =ROUNDUP(C16,0) -> 12 | E16: sticks | F16: Or order 3 m (118") custom lengths: 6 pcs
A17: Tile edge trim, window W11 outside corners | B17: 4 edges, 30" / 41 1/4" | C17: 2 | D17: =ROUNDUP(C17,0) -> 2 | E17: sticks
A18: 100% silicone, color-matched | B18: changes of plane, glass, curb, backsplash | C18: 6 | D18: =ROUNDUP(C18,0) -> 6 | E18: tubes | F18: Don't grout inside corners
A19: Tile leveling clips + wedges | B19: 12x24 tile count x 3 | C19: =(SUMIFS(Takeoff!$J$5:$J$64,Takeoff!$B$5:$B$64,"Bath floor tile")+SUMIFS(Takeoff!$J$5:$J$64,Takeoff!$B$5:$B$64,"Shower wall tile"))*1.25/2*3 -> 695.19796 | D19: =ROUNDUP(C19,0) -> 696 | E19: clips | F19: Order a 500- or 1,000-count kit
A20: LVP stair treads + risers (1F to 2F) | B20: Tread count not on plans; estimated | C20: 14 | D20: =ROUNDUP(C20,0) -> 14 | E20: sets | F20: HOLD: count the treads in the field. Stairs 'existing to remain' per A2.
A21: LVP flush stair nose (top landing) | B21: 1 at the 2F landing | C21: 1 | D21: =ROUNDUP(C21,0) -> 1 | E21: pc
A22: LVP reducer / transition to bath tile | B22: 3 bath doorways | C22: 3 | D22: =ROUNDUP(C22,0) -> 3 | E22: pcs | F22: Match LVP to tile height. Check the tile + membrane build-up.
A23: LVP end cap / threshold at exterior doors | B23: 1F entry, 2F foyer to porch, hall to garage | C23: 3 | D23: =ROUNDUP(C23,0) -> 3 | E23: pcs | F23: Garage door is the rated self-closing door, so the threshold must not interfere with latching
A24: Slab moisture test (Bedroom 3 and any 1F slab areas) | B24: RH probe per ASTM F2170 | C24: 1 | D24: =ROUNDUP(C24,0) -> 1 | E24: test | F24: Required by most LVP warranties over concrete
A25: Baseboard | B25: All rooms get new flooring, so base comes off | E25: LF | F25: Field measure. Not part of this takeoff.

Sheet Open Items & Risks
A1: Open Items & Contractor Risks
A2: Resolve the HOLD items before releasing the related PO line.
A4: # | B4: Item | C4: Why it matters | D4: Affects | E4: Needed from | F4: Priority
A5: 1 | B5: Kitchen window sill heights (W3, W5, W6) | C5: The backsplash is based on sills 4" above the counter (render). Each inch higher adds tile. Full band = 39 SF order vs 24 SF now. | D5: Backsplash tile | E5: Field measure | F5: HOLD
A6: 2 | B6: Cabinet sheet shows uppers in front of W5 and W3 | C6: The render shows no uppers over the windows. The hanging cabinet sheet must be revised before the cabinet PO. | D6: Cabinets, backsplash | E6: Designer | F6: HOLD
A7: 3 | B7: Range hood not on the cabinet sheet | C7: The render shows an insert hood in the uppers over the range. Confirm the hood model, CFM and duct route (A4 'RH'). | D7: Cabinets, backsplash | E7: Designer | F7: HIGH
A8: 4 | B8: 46" base right of the range | C8: It's in the render but dashed on the cabinet sheet and missing from A3. It affects CT3 (8.1 SF) and 21 SF of backsplash. | D8: Quartz, backsplash, cabinets | E8: Owner / designer | F8: HIGH
A9: 5 | B9: Product box coverage | C9: Summary column G has placeholder box sizes. Actual boxes change the SF delivered. | D9: All tile, LVP | E9: Supplier | F9: HIGH
A10: 6 | B10: Hall, closet and stair-landing areas are scaled | C10: About 190 SF of flooring was scaled off the plan because it isn't dimensioned. The permit says 'do not scale drawings.' | D10: Flooring | E10: Field measure | F10: MED
A11: 7 | B11: Stair tread count | C11: Not on the plans. Estimated at 14 treads. | D11: Stair treads | E11: Field count | F11: MED
A12: 8 | B12: Bath 2 niche in exterior wall | C12: Insulation and Title 24 continuity behind the niche. Alternative: a corner shelf. | D12: Niche, framing | E12: Contractor / T24 | F12: MED
A13: 9 | B13: W11 inside the Bath 3 shower | C13: Tempered glass is required. Waterproof the returns, slope the sill, use a vinyl or fiberglass frame. It's a leak and warranty risk. | D13: Wall tile, window | E13: Contractor | F13: MED
A14: 10 | B14: A5 window schedule locations mislabeled | C14: W7 is labeled Bath 3 but is on 2F; W11 is labeled Primary Bedroom but is in the Bath 3 shower. Correct before permit issuance or inspection. | D14: Windows | E14: Designer | F14: MED
A15: 11 | B15: Plan area labels vs dimensions | C15: Bath 1 label 60 SF vs 55.9 SF measured; Bedroom 3 label 116 SF vs 123.2 SF. This workbook uses dimensions. | D15: Flooring, bath tile | E15: Designer (FYI) | F15: LOW
A16: 12 | B16: Dye lot / lead time on patterned backsplash | C16: Patterned tile is often special order. A short order later won't match. Order in one lot and keep 1 spare box. | D16: Backsplash | E16: Purchasing | F16: MED
... A19: 15 | B19: Bath 2 shower size | C19: 32 3/8" framed-to-framed shrinks ~1" after board and tile. Verify it still meets the CPC 408.6 minimum (1,024 sq in, 30" circle). | D19: Bath 2 shower | E19: Contractor | F19: LOW
