Workbook

Sheet Dashboard
A1: Bateman Collective / Twin Home Buyer — Lead Tracking Dashboard
A2: Sources: "Facebook Leads" and "Google Leads" tabs (Bateman Collective leads portal export). Built 2026-07-21.
A4: Overview
A5: Total Leads | B5: =COUNTA('Facebook Leads'!$A$2:$A$12)+COUNTA('Google Leads'!$A$2:$A$45) -> 55
A6: Junk Leads (Test Lead + Duplicate Lead) | B6: =COUNTIF('Facebook Leads'!$F$2:$F$12,"Test Lead")+COUNTIF('Google Leads'!$F$2:$F$45,"Test Lead")+COUNTIF('Facebook Leads'!$F$2:$F$12,"Duplicate Lead")+COUNTIF('Google Leads'!$F$2:$F$45,"Duplicate Lead") -> 9
A7: Actionable Leads (Total − Junk) | B7: =B5-B6 -> 46
A8: Qualified Leads (Appointment + Contract) | B8: =COUNTIF('Facebook Leads'!$F$2:$F$12,"Qualified | Appointment")+COUNTIF('Google Leads'!$F$2:$F$45,"Qualified | Appointment")+COUNTIF('Facebook Leads'!$F$2:$F$12,"Qualified | Contract")+COUNTIF('Google Leads'!$F$2:$F$45,"Qualified | Contract") -> 3
A9: Qualified Rate (of Actionable Leads) | B9: =IFERROR(B8/B7,0) -> 0.065217391
A10: Note: "Junk" leads (Test Lead / Duplicate Lead) are internal test entries and known duplicates from the portal; they are excluded from Actionable Leads and the Qualified Rate denominator.
A12: Leads by Source | D12: Leads by Disposition
A13: Source | B13: Count | D13: Disposition | E13: Count
A14: Facebook | B14: =COUNTIF('Facebook Leads'!$H$2:$H$12,"Facebook")+COUNTIF('Google Leads'!$H$2:$H$45,"Facebook") -> 11 | D14: Qualified | Appointment | E14: =COUNTIF('Facebook Leads'!$F$2:$F$12,"Qualified | Appointment")+COUNTIF('Google Leads'!$F$2:$F$45,"Qualified | Appointment") -> 1
A15: Google | B15: =COUNTIF('Facebook Leads'!$H$2:$H$12,"Google")+COUNTIF('Google Leads'!$H$2:$H$45,"Google") -> 42 | D15: Qualified | Contract | E15: =COUNTIF('Facebook Leads'!$F$2:$F$12,"Qualified | Contract")+COUNTIF('Google Leads'!$F$2:$F$45,"Qualified | Contract") -> 2
A16: Print | B16: =COUNTIF('Facebook Leads'!$H$2:$H$12,"Print")+COUNTIF('Google Leads'!$H$2:$H$45,"Print") -> 2 | D16: Unqualified Seller | Other | E16: =COUNTIF('Facebook Leads'!$F$2:$F$12,"Unqualified Seller | Other")+COUNTIF('Google Leads'!$F$2:$F$45,"Unqualified Seller | Other") -> 6
D17: Unqualified Seller | Poor Location | E17: =COUNTIF('Facebook Leads'!$F$2:$F$12,"Unqualified Seller | Poor Location")+COUNTIF('Google Leads'!$F$2:$F$45,"Unqualified Seller | Poor Location") -> 5
D18: Unqualified Seller | Retail | E18: =COUNTIF('Facebook Leads'!$F$2:$F$12,"Unqualified Seller | Retail")+COUNTIF('Google Leads'!$F$2:$F$45,"Unqualified Seller | Retail") -> 4
D19: Unqualified Seller | Already Listed | E19: =COUNTIF('Facebook Leads'!$F$2:$F$12,"Unqualified Seller | Already Listed")+COUNTIF('Google Leads'!$F$2:$F$45,"Unqualified Seller | Already Listed") -> 1
D20: Non-Seller | Other | E20: =COUNTIF('Facebook Leads'!$F$2:$F$12,"Non-Seller | Other")+COUNTIF('Google Leads'!$F$2:$F$45,"Non-Seller | Other") -> 8
D21: Non-Seller | SPAM | E21: =COUNTIF('Facebook Leads'!$F$2:$F$12,"Non-Seller | SPAM")+COUNTIF('Google Leads'!$F$2:$F$45,"Non-Seller | SPAM") -> 4
D22: No Contact | E22: =COUNTIF('Facebook Leads'!$F$2:$F$12,"No Contact")+COUNTIF('Google Leads'!$F$2:$F$45,"No Contact") -> 13
D23: Test Lead | E23: =COUNTIF('Facebook Leads'!$F$2:$F$12,"Test Lead")+COUNTIF('Google Leads'!$F$2:$F$45,"Test Lead") -> 8
D24: Duplicate Lead | E24: =COUNTIF('Facebook Leads'!$F$2:$F$12,"Duplicate Lead")+COUNTIF('Google Leads'!$F$2:$F$45,"Duplicate Lead") -> 1
D25: (No Disposition Set) | E25: =COUNTBLANK('Facebook Leads'!$F$2:$F$12)+COUNTBLANK('Google Leads'!$F$2:$F$45) -> 2
A28: Google Ads Cost Analysis
A29: Google Ads Spend (this period) | B29: 25400
A30: Google Leads Count | B30: =$B$15 -> 42
A31: Qualified Leads from Google | B31: =COUNTIF('Google Leads'!$F$2:$F$45,"Qualified | Appointment")+COUNTIF('Google Leads'!$F$2:$F$45,"Qualified | Contract") -> 3
A32: Cost Per Lead (Google) | B32: =IFERROR($B$29/B30,0) -> 604.7619
A33: Cost Per Qualified Lead (Google) | B33: =IFERROR($B$29/B31,0) -> 8466.6667
A35: Google Ads spend has not been provided yet — the yellow cell above defaults to $0. Enter the real spend to populate cost-per-lead figures.

Sheet Facebook Leads
A1: Date | B1: Name | C1: Address | D1: Phone Number | E1: Email | F1: Disposition | G1: Notes | H1: Source | I1: Campaign | J1: Tracking Link
A2: 7/20/2026 1:06:14 | B2: Jeffrey Bryant | C2: 26385 Adrian Ave, Hayward, CA, USA | D2: 9254372355 | E2: jeffyb@comcast.net | H2: Facebook | I2: BOFU - Bateman
A3: 7/17/2026 11:23:39 | B3: Wendy Zampardi | C3: 3119 Hillside Drive, Fortuna, CA, USA | D3: 7077232369 | E3: wzampardi@gmail... | F3: Non-Seller | Other | G3: The property is a vacant la... | H3: Facebook | I3: BOFU - Bateman
A4: 7/17/2026 3:37:25 | C4: 1 Green Point Lane, Novato, CA, USA | D4: 9162135913 | F4: Unqualified Seller | Already Listed | G4: The listing agent is also the... | H4: Facebook | I4: BOFU - Bateman
A5: 7/14/2026 11:33:18 | B5: Test Lead | C5: 555 W 1275 N, Lehi, UT, USA | D5: 3852528245 | E5: test@gmail.com | F5: Test Lead | H5: Facebook
A6: 7/13/2026 8:37:00 | B6: SAN FRANCSCO CA | C6: San Francisco, CA | D6: 4157562546 | F6: No Contact | G6: Called the lead but he ment... | H6: Facebook | I6: BOFU - Bateman | J6: https://app.calltrackingmet...
A7: 7/13/2026 10:15:23 | C7: Sacramento, CA, USA | D7: 9162876881 | F7: No Contact | H7: Facebook | I7: BOFU - Bateman
A8: 7/13/2026 10:14:35 | C8: 3726ja | D8: 9162876881 | F8: No Contact | H8: Facebook | I8: BOFU - Bateman
A9: 7/11/2026 8:15:30 | C9: 424 mark ave | D9: 7736907284 | F9: No Contact | H9: Facebook | I9: BOFU - Bateman
A10: 7/11/2026 2:40:00 | B10: MODESTO CA | C10: Modesto, CA | D10: 2096147838 | F10: Non-Seller | SPAM | H10: Facebook | I10: BOFU - Bateman
A11: 7/11/2026 1:52:47 | C11: Mariarivera @$icloud | D11: 2097719288 | F11: No Contact | H11: Facebook | I11: BOFU - Bateman
A12: 7/10/2026 8:39:36 | C12: 3770 Lincoln Boulevard, Oroville, CA, USA | D12: 5309220470 | F12: No Contact | H12: Facebook | I12: BOFU - Bateman

Sheet Google Leads
A1: Date | B1: Name | C1: Address | D1: Phone Number | E1: Email | F1: Disposition | G1: Notes | H1: Source | I1: Campaign | J1: Tracking Link
A2: 7/20/2026 2:50:34 | B2: Stephanie Aguilar | C2: 1645 Concord Ave | D2: 5593956021 | E2: stephaniecambero... | F2: Unqualified Seller | Other | G2: Not in a rush to sell, just w... | H2: Google | I2: 23913739190
A3: 7/20/2026 12:04:5 | C3: 1200 DeKalb Ave NE, Atlanta, GA, USA | D3: 4085153786 | F3: Unqualified Seller | Poor Location | G3: Out of Twin Home Buyer's... | H3: Google | I3: 23913739190
A4: 7/20/2026 1:34:09 | B4: Alyssia Esquivel | C4: 1270 South Rose | D4: 2097185350 | E4: alyssiaesquivel98... | H4: Google | I4: 23913739190
A5: 7/16/2026 10:52:19 | B5: Chris J. Giro | C5: 18 Hampton Rd, Occidental, CA 95465, USA | D5: 7072929001 | E5: sebastopolglass@... | F5: Unqualified Seller | Other | G5: We passed on this lead - a... | H5: Google | I5: 23913739190
A6: 7/15/2026 9:46:34 | B6: Jesse Davis | C6: 2440 Orchard Ln, Martinez, CA, USA | D6: 9258122778 | E6: yozerzjessedavis... | F6: Non-Seller | Other | G6: The property is already for... | H6: Google | I6: 23913739190
A7: 7/15/2026 4:16:54 | B7: Roger William | C7: 2318 Amboy Avenue, Stockton, CA, USA | D7: 9255658415 | E7: rogerwjohnson1@... | F7: No Contact | G7: The lead is unresponsive | H7: Google | I7: 23913739190
A8: 7/14/2026 1:06:17 | B8: Leticia Araujo-Perez | C8: 4029 Folsom Street, San Francisco, CA, USA | D8: 5103947767 | E8: leticiaaraujoperez... | F8: Non-Seller | Other | G8: The lead decided to go wit... | H8: Google | I8: 23913739190
A9: 7/11/2026 3:45:00 | B9: J WEGLEITNER | C9: Vallejo, CA | D9: 7077126984 | F9: Non-Seller | SPAM | G9: Spoke to this lead/someon... | H9: Google | I9: BOFU - Bateman | J9: https://app.calltrackingmet...
A10: 7/11/2026 6:37:40 | C10: 309 De Anza Drive, Vallejo, CA, USA | D10: 7076233206 | F10: No Contact | H10: Google | I10: 23913739190
A11: 7/10/2026 9:59:00 | B11: KEUING WALTER | C11: Oakland:Fruitvale Da, CA | D11: 5104852812 | F11: Non-Seller | Other | G11: The lead is asking if we bu... | H11: Print | J11: https://app.calltrackingmet...
A12: 7/8/2026 6:58:29 | B12: Baljit Singh | C12: 867 Osprey Drive, Lathrop, CA, USA | D12: 9255010086 | E12: singhbaljit01@iclo... | F12: Unqualified Seller | Other | G12: We passed on this lead | H12: Google | I12: 23913739190
A13: 7/7/2026 5:13:41 PM | B13: MK Ding | C13: 1549 5th Avenue, Oakland, CA | D13: 6508420448 | E13: mkding71@gmail.c... | F13: Qualified | Appointment | G13: Appointmnet completed - w... | H13: Google | I13: 23913739190
A14: 7/6/2026 7:54:57 | C14: 1070 Bare Oak Ave | D14: 5593602132 | F14: No Contact | H14: Google | I14: 23913739190
A15: 7/6/2026 2:05:23 | B15: Tony Bal | C15: 12 E St, Empire, CA, USA | D15: 2093805564 | E15: devraz_78@yahoo... | F15: Unqualified Seller | Other | G15: We passed on this lead | H15: Google | I15: 23913739190
A16: 7/4/2026 11:31:22 | B16: Edward Ceja | C16: 615 4th Court, Mendota, CA, USA | D16: 5593887135 | E16: anthony4990m@g... | F16: No Contact | G16: The lead became unrespon... | H16: Google | I16: 23913739190
A17: 7/3/2026 1:46:59 | B17: Daniel Gamblin Jordan | C17: 645 Russell St, Vallejo, CA, USA | D17: 7075340307 | E17: danieljordan2332... | F17: Unqualified Seller | Other | G17: Daniel Gamblin Jordan - 6... | H17: Google | I17: 23913739190
A18: 6/30/2026 4:30:2 | C18: 2328 Lafayette Drive, Antioch, CA, USA | D18: 9255868512 | F18: No Contact | H18: Google | I18: 23913739190
A19: 6/28/2026 7:47:29 | B19: Robert Gunn | C19: 3375 17th Street, Apt 311 San Francisco, CA | D19: 4157941602 | E19: gunncomm@com... | F19: Qualified | Contract | G19: Contract already sent - wai... | H19: Google | I19: 23913739190
A20: 6/27/2026 2:51:25 | B20: Rosendo Mercado | C20: 5602 Walerga Road, Sacramento, CA, USA | D20: 9168212648 | E20: mercadoross@ya... | F20: Unqualified Seller | Other | G20: Lead says that someone fill... | H20: Google | I20: 23913739190
A21: 6/24/2026 4:53:57 | B21: Maria Lemons | C21: 955 W Clubhouse Dr, Prescott, AZ, USA | D21: 9283087823 | E21: alize9lemons@gm... | F21: Unqualified Seller | Poor Location | H21: Google | I21: 23913739190
A22: 6/24/2026 4:15:20 | C22: 1904 Everest Place, Tracy, CA, USA | D22: 4089871053 | F22: No Contact | H22: Google | I22: 23913739190
A23: 6/23/2026 9:21:51 | C23: 5053 Veranda Terrace, Davis, CA, USA | D23: 7076850229 | F23: Non-Seller | Other | G23: Lead mentioned that he wa... | H23: Google | I23: 23913739190
A24: 6/22/2026 11:21:42 | B24: Martha Reece | C24: 5475 East Illinois Avenue, Fresno, CA, USA | D24: 5599388160 | E24: greeg1035@gmail... | F24: Qualified | Contract | G24: The lead already signed th... | H24: Google | I24: 23913739190
A25: 6/22/2026 1:09:55 | B25: Kashov Sharma | C25: 1000 W 26th St unit 213, Austin, TX, USA | D25: 8318692049 | E25: pratibh55@gmail.com | F25: Non-Seller | Other | G25: Lead submitted a PPC form... | H25: Google | I25: 23913739190
A26: 6/20/2026 7:10:54 | B26: Oscar Cantu | C26: 9 West Yorkshire Drive, Stockton, CA, USA | D26: 2094566874 | E26: oscarcantu06@m... | F26: Non-Seller | Other | G26: For property visit on June... | H26: Google | I26: 23913739190
A27: 6/19/2026 11:52:12 | B27: Thomas Burke | C27: 191 Orange St, Kingsburg, CA, USA | D27: 5598451968 | E27: dairychemworkz@... | F27: Unqualified Seller | Retail | H27: Google | I27: 23913739190
A28: 6/16/2026 5:19:40 | B28: Jaimin Patel | C28: 104 Woodbridge Cir, San Mateo, CA, USA | D28: 4152861222 | E28: tgovind@excite.com | F28: Non-Seller | SPAM | G28: Called the lead and said th... | H28: Google | I28: 23913739190
A29: 6/15/2026 10:39:0 | B29: MARCHETTI SEBAS | C29: San Mateo, CA | D29: 6505200300 | F29: No Contact | G29: The lead became unrespon... | H29: google | J29: https://app.calltrackingmet...
A30: 6/15/2026 11:38:00 | B30: WIRELESS CALLER | C30: Los Altos, CA | D30: 6505189183 | F30: Unqualified Seller | Retail | G30: Seller wants to sell but decl... | H30: google | J30: https://app.calltrackingmet...
A31: 6/14/2026 3:49:36 | B31: Jhanel Kies | C31: 2454 Vista Grande, Fairfield, CA, USA | D31: 6505189183 | E31: C1011w@yahoo.com | F31: Unqualified Seller | Retail | G31: Seller wants to sell but decl... | H31: Google | I31: 23913739190
A32: 6/13/2026 12:17:08 | C32: 8926 Mountain Home Court, Elk Grove, CA | D32: 2092773700 | F32: Non-Seller | Other | G32: Lead is not the property ow... | H32: Google | I32: 23913739190
A33: 6/13/2026 10:13:4 | B33: Gurjit Chahal | C33: 15055 Hollyock Ct, Lathrop, CA, USA | D33: 2094823376 | E33: gurjit.chahal95@o... | F33: Unqualified Seller | Retail | G33: we are passing low equity | H33: Google | I33: 23913739190
A34: 6/11/2026 2:44:12 | B34: Name Test | C34: 4545 E Golden Autumn Vw, Eagle Mountain | D34: 4545454545 | E34: Test@gmail.com | F34: Test Lead | H34: Google
A35: 6/11/2026 2:33:59 | B35: Test Lead Only Test | C35: 170 Glen Way, Atlanta, GA, USA | D35: 5103945339 | E35: test@leadgmail.com | F35: Test Lead | H35: Google
A36: 6/11/2026 2:13:00 | B36: OAKLAND CA | C36: Oakland:Trinidad Da, CA | D36: 5103945339 | F36: Test Lead | H36: Print | J36: https://app.calltrackingmet...
A37: 6/11/2026 2:05:50 | B37: Juan Diaz | C37: 100 Palm Avenue, San Carlos, CA, USA | D37: 5108001662 | E37: bryan@twinhome... | F37: Duplicate Lead | G37: Existing lead - May 03, 2024 | H37: Google | I37: 23913739190
A38: 6/11/2026 1:17:20 | C38: 4917 N Holt Ave apt 103, Fresno CA 93705 | D38: 5593497823 | F38: Non-Seller | SPAM | G38: This seller is offering his ne... | H38: Google | I38: 23913739190
A39: 6/9/2026 4:45:00 | B39: WIRELESS CALLER | C39: Clovis, CA | D39: 5597671593 | F39: Unqualified Seller | Poor Location | H39: google | J39: https://app.calltrackingmet...
A40: 6/9/2026 3:11:41 PM | B40: Test Lead | C40: 777 W 2260 N, Lehi, UT | D40: 7777777777 | E40: test@gmail.com | F40: Test Lead | H40: Google
...
